Workbook

Sheet Key
A2: Note this algorithm works by OR matching - if any record matches any code in any column it will mark the participant as a case, otherwise they are considered a control
A4: Key | B4: ALL | D4: [code].X will be matched with any string that starts [code] then followed by any numbers
D5: [code] will be matched exactly only
D6: Please split with commas
B9: Primary Care | D9: If Use Primary Care Code does not contain "Yes" the algorithm will ignore Primary Care Data
D10: If Use Primary Care Code contains "Yes", additional variables will be created setting participants to case, control or missing from Primary Care
D11: For this to work, one of the following must be true:
D12: 1) Match ICD10 Primary Codes = "Yes" : this will use the ICD10 column to match to the read codes - please see sheet Primary Care Matching Key for details
D13: NOTE: This should not be used for dagger and asterisk ICD codes
D14: 2) Read v2 or Read v3 is non-empty: this will match only the codes shown in these cells to the primary care data
B18: Prevalent/Incident: | D18: By default variables are reported as binary present or absent;
D19: if "YES" is in the prevalent/incident column then each case participant will be marked prevalent or incident
D20: and a date field of first event for each type (HES, Death Certificate, Primary, Self-report) will be given
D21: Dates will be approximated as the midpoint between last clear report and first present report if missing
D22: Where multiple dates exist for the same event report, the earliest date will be taken if incident; the median date will be taken if prevalent
D23: (e.g. ifa followup survey reports a conditions but the preliminary does not, the date will be set as the midpoint of the two reports)
B26: Fields Used from UK Biobank
B27: 40013, 40017, 41203, 41205 | D27: ICD-9 codes
B28: 40006, 40016, 41202, 41204 | D28: ICD-10 codes
B29: 40001, 40002 | D29: Death Certification
B30: 40011 | D30: Cancer Histology
B31: 20001, 20002, 20004, 6150, 6152, 6153, 6177 | D31: Self-report
B34: Password | D34: happybunny

Sheet Primary Care Matching Key
A1: Adaption of the UK Biobank download from http://biobank.ndph.ox.ac.uk/showcase/showcase/auxdata/primarycare_codings.zip
A2: The best explanation of the superset of these mappings is : http://biobank.ctsu.ox.ac.uk/crystal/crystal/docs/first_occurrences_outcomes.pdf
A6: read_v2_icd10 | C6: Table 2 shows the UK Biobank mappings for their first occurances outcomes | K6: Table 2
I7: Included? | K7: Mapping type
C8: Contains only the 1:1 mapping terms | I8: Yes | K8: 1:1 map
I9: No | K9: range map: read v2 term maps to any in a range of ICD10 codes
C10: If you require a more sensitive treatment of the
C11: Read V2 codes, look up your required codes using the | I11: No | K11: combination - multiple ICD10 codes given. Any are possible cross maps
C12: primarycare_codings.zip link above
C13: and put in the Read V2 column on the control sheet | I13: No | K13: Asterisk code
I14: No | K14: Dagger and asterisk code paid
I16: No | K16: Dagger code
I17: No | K17: Plus sign used - two ICD10 codes are both needed to describe this read v2 code
A21: read_ctv3_icd10 | C21: Contains only the D and E mappings (Exact and Default)
C23: If you require a more sensitive treatment of the
C24: Read V3 codes, look up your required codes using the
C25: primarycare_codings.zip link above
C26: and put in the Read V3 column on the control sheet

Sheet Definitions
A1: Completer | B1: Outcome name | C1: Suggested variable name | D1: ICD-9 codes | E1: ICD-10 codes | F1: Death 40001, 40002 | G1: Cancer Histology | H1: Self-report 20001 | I1: Self-report 20002 | J1: Self-report 20004 | K1: Self-report 6150 | L1: Self-report 6152 | M1: Self-report 6153 | N1: Self-report 6177 | O1: Procedures OPCS4 | P1: Procedures OPCS3 | Q1: Use Primary Care | R1: Match ICD10 Primary Care Codes | S1: Read V3 Primary Care Codes | T1: Read V2 Primary Care Codes | U1: Prevalent/Incident | V1: Comments on definition | W1: Other comments
A2: Adam | B2: Aortic aneurysm | C2: aa | D2: 441.X | E2: I71.X | F2: I71.X | I2: 1492, 1591 | J2: 1104 | Q2: NO | R2: NO | U2: No | V2: Non-CHD CVD
A3: Adam | B3: 'Hard' coronary artery disease | C3: cad_hard | D3: 410.X, 411.X, 412.X | E3: I21.X, I22.X, I23.X, I24.X, I25.2 | F3: I21.X, I22.X, I23.X, I24.X, I25.2 | I3: 1075 | J3: 1070, 1095, 1523 | K3: 1 | O3: K40.X, K41.X, K42.X, K43.X, K44.X, K45.X, K46.X, K49.X, K50.1, K50.2, K50.4, K75.X | Q3: No | U3: No | V3: Used for GWAS analysis of coronary disease in by the UKBB CardioMetabolic Consortium CAD group (see Nelson et al, Nature Genetics, 2017)
A4: Adam | B4: 'Intermediate' coronary artery disease | C4: cad_int | D4: 410.X, 411.X, 412.X, 414.0.X, 414.8.X, 414.9.X | E4: I21.X, I22.X, I23.X, I24.X, I25.1, I25.2, I25.5, I25.6, I25.8, I25.9 | F4: I21.X, I22.X, I23.X, I24.X, I25.1, I25.2, I25.5, I25.6, I25.8, I25.9 | I4: 1075 | J4: 1070, 1095, 1523 | K4: 1 | O4: K40.X, K41.X, K42.X, K43.X, K44.X, K45.X, K46.X, K49.X, K50.1, K50.2, K50.4, K75.X | Q4: No | U4: No | V4: Revised definition inbetween the 'soft' and 'hard' above, being used by the UKBB CardioMetabolic Consortium CAD group currently
A5: Adam | B5: 'Soft' coronary artery disease | C5: cad_soft | D5: 410.X, 411.X, 412.X, 413.X, 414.0.X, 414.8.X, 414.9.X | E5: I20.X, I21.X, I22.X, I23.X, I24.X, I25.1, I25.2, I25.5, I25.6, I25.8, I25.9 | F5: I20.X, I21.X, I22.X, I23.X, I24.X, I25.1, I25.2, I25.5, I25.6, I25.8, I25.9 | I5: 1074, 1075 | J5: 1070, 1095, 1523 | K5: 1, 2 | O5: K40.X, K41.X, K42.X, K43.X, K44.X, K45.X, K46.X, K49.X, K50.1, K50.2, K50.4, K75.X | Q5: No | U5: No | V5: Used for GWAS analysis of coronary disease in by the UKBB CardioMetabolic Consortium CAD group (see Nelson et al, Nature Genetics, 2017)
A6: Adam | B6: Heart failure (including cardiomyopathy) | C6: hf_cmp | D6: 402.01, 402.11, 402.91, 404.01, 404.11, 404.91, 404.03, 404.13, 404.93, 425.X, 428.X | E6: I11.0, I13.0, I13.2, I25.5, I50.X, I42.X | F6: I11.0, I13.0, I13.2, I25.5, I50.X, I42.X | I6: 1076, 1079, 1588 | Q6: No | U6: No | V6: Non-CHD CVD (used in Emdin et al, Circulation 2018)
A7: Adam | B7: Thoracic aortic aneurysm | C7: taa | D7: 441.1.X, 441.2.X | E7: I71.1, I71.2 | F7: I71.1, I71.2 | I7: - | Q7: No | U7: No | V7: Non-CHD CVD
A8: Adam | B8: UKB's algorithmically defined intracerebral haemorrhage | C8: ukb_ich | D8: 431.X | E8: I61.X | F8: I61.X | I8: 1491 | O8: - | Q8: No | U8: No | V8: Provided by UK Biobank (fields 42010/42011). Subset of ukb_stroke
A9: Adam | B9: UKB's algorithmically defined myocardial infarction | C9: ukb_mi | D9: 410.X, 411.0.X, 412.X, 429.79 | E9: I21.X, I22.X, I23.X, I24.1, I25.2 | F9: I21.X, I22.X, I23.X, I24.1, I25.2 | I9: 1075 | O9: - | Q9: No | U9: No | V9: Provided by UK Biobank (fields 42000/42001). NB: only MI, not all coronary disease
A10: Adam | B10: UKB's algorithmically defined NSTEMI | C10: ukb_nstemi | D10: 410.7.X | E10: I21.4, I21.9, I22.9 | F10: I21.4, I21.9, I22.9 | I10: - | O10: - | Q10: No | U10: No | V10: Provided by UK Biobank (fields 42004/42005). Subset of the MI variable
A11: Adam | B11: UKB's algorithmically defined subarachnoid haemorrhage | C11: ukb_sah | D11: 430.X | E11: I60.X | F11: I60.X | I11: 1086 | O11: - | Q11: No | U11: No | V11: Provided by UK Biobank (fields 42012/42013). Subset of ukb_stroke
A12: Adam | B12: UKB's algorithmically defined STEMI | C12: ukb_stemi | D12: 410.0.X, 410.1.X, 410.2.X, 410.3.X, 410.4.X, 410.5.X, 410.6.X, 410.8.X, 410.9.X | E12: I21.0, I21.1 I21.2, I21.3, I22.0, I22.1, I22.8 | F12: I21.0, I21.1 I21.2, I21.3, I22.0, I22.1, I22.8 | I12: - | O12: - | Q12: No | U12: No | V12: Provided by UK Biobank (fields 42002/42003). Subset of the MI variable
A13: Adam | B13: UKB's algorithmically defined ischaemic stroke | C13: ukb_stri | D13: 434.X, 436.X | E13: I63.X, I64.X | F13: I63.X, I64.X | I13: 1583 | O13: - | Q13: No | U13: No | V13: Provided by UK Biobank (fields 42008/42009). Subset of ukb_stroke
A14: Adam | B14: UKB's algorithmically defined stroke | C14: ukb_stroke | D14: 430.X, 431.X, 434.X, 436.X | E14: I60.X, I61.X, I63.X, I64.X | F14: I60.X, I61.X, I63.X, I64.X | I14: 1081, 1086, 1491, 1583 | O14: - | Q14: No | U14: No | V14: Provided by UK Biobank (fields 42006/42007).
A15: Adam | B15: Venous thromboembolism | C15: vte | D15: 415.1, 451.1, 452.X, 453.0, 453.4.X, 453.9.X, | E15: I26.X, I80.1, I80.2, I81.X, I82.0 | F15: I26.X, I80.1, I80.2, I81.X, I82.0 | I15: 1068, 1093, 1094 | L15: 5,7 | O15: L90.2 | Q15: No | U15: No | V15: Non-CHD CVD (used in Emdin et al, Circulation 2018)
A16: Amy | B16: Schizophrenia | C16: sch_1 | D16: 295.X | E16: F20.X, F25.X | F16: F20.X, F25.X | I16: 1289 | Q16: Yes | R16: Yes | U16: No | V16: Schizophrenia
A17: Amy | B17: Schizophrenia inc schizoaffective disorder | C17: sch_2 | D17: 295.X, 301.22, 301.20, 301.21 | E17: F20.X, F25.X, F21.X, F60.1.X | F17: F20.X, F25.X, F21.X, F60.1.X | I17: 1289 | Q17: Yes | R17: Yes | U17: No | V17: Schizophrenia & schizoaffective disorder
A18: Amy | B18: All Cancer | C18: ca_all | D18: 14.X, 15.X,16.X,17.X, 18.X, 19.X, 20.X, V10.X | E18: C.X, Z85.X | F18: C.X, Z85.X | G18: .X | H18: .X
A19: Amy | B19: Tachycardia with palpations | C19: aftap | D19: 427.3.X, 427.0.X, 427.4.X, 785.0.X, 427.6.X, | E19: I48.X, I47.X, I49.0.X, I49.1.X, I49.2.X, I49.3.X, I49.4.X, R00.0, R00.2 | F19: I48.X, I47.X, I49.0.X, I49.1.X, I49.2.X, I49.3.X, I49.4.X, R00.0, R00.2 | I19: 1471, 1483, 1485, 1487 | J19: - | K19: - | L19: - | M19: - | N19: - | O19: - | Q19: NO | U19: No | V19: Extended af to include tachycardia and palpations; coffee-CVD manuscript; NB: hr>100 must be added seperately via 102 & 4149
A20: Amy | B20: Tachycardia | C20: afta | D20: 427.3.X, 427.0.X, 427.4.X, 785.0.X, | E20: I48.X, I47.X, I49.0.X, R00.0, | F20: I48.X, I47.X, I49.0.X, R00.0, | I20: 1487, 1471, 1483 | J20: - | K20: - | L20: - | M20: - | N20: - | O20: - | Q20: NO | U20: No | V20: Extended af to include tachycardia; coffee-CVD manuscript NB: hr>100 must be added seperately via 102 & 4149
A21: Amy | B21: Fracture of Femur | C21: fof | D21: 820.X, 821.X, | E21: S72.X | F21: S72.X | I21: 1648, 1649 | Q21: NO | U21: No
A22: Amy | B22: osteoporosis | C22: osteo | D22: 733.00 , 733.01, 733.02 , 733.03 , 733.09 | E22: M80.X, M81.X, M82.X, | F22: M80.X, M81.X, M82.X, | I22: 1309 | Q22: NO | U22: No
A23: Amy | B23: osteoporosis plus osteopenia | C23: osteo_plus | D23: 733.00 , 733.01, 733.02 , 733.03 , 733.09 | E23: M80.X, M81.X, M82.X, | F23: M80.X, M81.X, M82.X, | I23: 1309, 1617, | Q23: NO | U23: No
A24: Amy | B24: fracture of Forearm | C24: frac_fore | D24: 813.X, 733.12 | E24: S52.X, S62.9.X, M80.03 , M8083, | F24: S52.X, S62.9.X, M80.03 , M8083, | I24: 1634, 1635, 1636 | Q24: NO | U24: No | V24: Fragility Fracture Codes, based on https://www.ncbi.nlm.nih.gov/pmc/articles/PMC6358485/#SD2 , table 22, Edited by Amy
A25: Amy | B25: fracture of Upper arm | C25: frac_arm | D25: 812.X, 733.11 | E25: S42.2.X, S42.3.X, S42.4.X, S42.7.X, S42.8.X, S42.9.X, M8001, M8002, M8081, M8082 | F25: S42.2.X, S42.3.X, S42.4.X, S42.7.X, S42.8.X, S42.9.X, M8001, M8002, M8081, M8082 | I25: 1633 | Q25: NO | U25: No | V25: Fragility Fracture Codes, based on https://www.ncbi.nlm.nih.gov/pmc/articles/PMC6358485/#SD2 , table 22, Edited by Amy
A26: Amy | B26: fracture of Hip | C26: frac_hip | D26: 820.X, 733.14 | E26: S72.0.X, S72.1.X, S72.2.X, | F26: S72.0.X, S72.1.X, S72.2.X, | I26: 1648 | Q26: NO | U26: No | V26: Fragility Fracture Codes, based on https://www.ncbi.nlm.nih.gov/pmc/articles/PMC6358485/#SD2 , table 22, Edited by Amy
A27: Amy | B27: fracture of Vertebrae | C27: frac_vert | D27: 805.X, 806.X, 733.13 | E27: S12.0.X, S12.1.X, S12.2.X, S12.3.X, S12.4.X, S12.5.X, S12.6.X, S12.7.X, S22.0.X, S22.1.X, S32.0.X, M484.X, M485.X, M8008, M8088 | F27: S12.0.X, S12.1.X, S12.2.X, S12.3.X, S12.4.X, S12.5.X, S12.6.X, S12.7.X, S22.0.X, S22.1.X, S32.0.X, M484.X, M485.X, M8008, M8088 | I27: 1646 | Q27: NO | U27: No | V27: Fragility Fracture Codes, based on https://www.ncbi.nlm.nih.gov/pmc/articles/PMC6358485/#SD2 , table 22, Edited by Amy
A28: Amy | B28: fracture of Pelvis | C28: frac_pelvis | D28: 808.X | E28: S32.1.X, S32.2.X, S32.3.X, S32.4.X, S32.5.X, S32.6.X,S32.7.X,S32.8.X, S32.9.X | F28: S32.1.X, S32.2.X, S32.3.X, S32.4.X, S32.5.X, S32.6.X,S32.7.X,S32.8.X, S32.9.X | I28: 1647 | Q28: NO | U28: No | V28: Fragility Fracture Codes, based on https://www.ncbi.nlm.nih.gov/pmc/articles/PMC6358485/#SD2 , table 22, Edited by Amy
A29: Amy | B29: fracture of Femur | C29: frac_femur | D29: 821.X, 733.15 | E29: S72.3.X, S72.4.X, S72.5.X, S72.6.X, S72.7.X, S72.8.X, S72.9.X, M8005, M8085 | F29: S72.3.X, S72.4.X, S72.5.X, S72.6.X, S72.7.X, S72.8.X, S72.9.X, M8005, M8085 | I29: 1649 | Q29: NO | U29: No | V29: Fragility Fracture Codes, based on https://www.ncbi.nlm.nih.gov/pmc/articles/PMC6358485/#SD2 , table 22, Edited by Amy
A30: Amy | B30: fracture of Lower leg | C30: frac_leg | D30: 823.X, 733.16 | E30: S82.1.X, S82.2.X, S82.3.X, S82.4.X, M8006, M8086 | F30: S82.1.X, S82.2.X, S82.3.X, S82.4.X, M8006, M8086 | I30: 1651, 1652, 1653, | Q30: NO | U30: No | V30: Fragility Fracture Codes, based on https://www.ncbi.nlm.nih.gov/pmc/articles/PMC6358485/#SD2 , table 22, Edited by Amy
A31: Amy | B31: fracture of Patella | C31: frac_pat | D31: 822.X | E31: S82.0.X | F31: S82.0.X | I31: 1650 | Q31: NO | U31: No | V31: Fragility Fracture Codes, based on https://www.ncbi.nlm.nih.gov/pmc/articles/PMC6358485/#SD2 , table 22, Edited by Amy
A32: Amy | B32: fracture of Ankle | C32: frac_ank | D32: 824.X | E32: S82.5.X, S82.6.X, S82.7.X, S82.8.X, S82.9.X, M8007, M8087 | F32: S82.5.X, S82.6.X, S82.7.X, S82.8.X, S82.9.X, M8007, M8087 | I32: 1654 | Q32: NO | U32: No | V32: Fragility Fracture Codes, based on https://www.ncbi.nlm.nih.gov/pmc/articles/PMC6358485/#SD2 , table 22, Edited by Amy
A33: Amy | B33: fracture of Rib | C33: frac_rib | D33: 807.0.X , 807.1.X, | E33: S22.3.X, S22.4.X, S22.5.X | F33: S22.3.X, S22.4.X, S22.5.X | I33: 1644, | Q33: NO | U33: No | V33: Fragility Fracture Codes, based on https://www.ncbi.nlm.nih.gov/pmc/articles/PMC6358485/#SD2 , table 22, Edited by Amy
A34: Amy | B34: fracture of Scapula | C34: frac_scap | D34: 811.X | E34: S42.1.X | F34: S42.1.X | I34: 1632 | Q34: NO | U34: No | V34: Fragility Fracture Codes, based on https://www.ncbi.nlm.nih.gov/pmc/articles/PMC6358485/#SD2 , table 22, Edited by Amy
A35: Amy | B35: fracture of Sternum | C35: frac_ster | D35: 807.2.X, 807.3.X | E35: S22.2.X | F35: S22.2.X | I35: 1645 | Q35: NO | U35: No | V35: Fragility Fracture Codes, based on https://www.ncbi.nlm.nih.gov/pmc/articles/PMC6358485/#SD2 , table 22, Edited by Amy
A36: Amy | B36: fracture of Clavicle | C36: frac_calv | D36: 810.X | E36: S42.0.X | F36: S42.0.X | I36: 1631 | Q36: NO | U36: No | V36: Fragility Fracture Codes, based on https://www.ncbi.nlm.nih.gov/pmc/articles/PMC6358485/#SD2 , table 22, Edited by Amy
A37: Amy | B37: fracture of site unspecified | C37: frac_unk | D37: 733.10, 733.19 | E37: M8000, M8080, M810.X, Z87310 | F37: M8000, M8080, M810.X, Z87310 | Q37: NO | U37: No | V37: Fragility Fracture Codes, based on https://www.ncbi.nlm.nih.gov/pmc/articles/PMC6358485/#SD2 , table 22, Edited by Amy
A38: Amy | B38: fracture anywhere | C38: frac_all | D38: 80.X, 81.X, 82.X, 733.1.X | E38: S02.X, S12.X, S22.X, S32.X, S42.X, S52.X, S62.X, S72.X, S82.X, S92.X, M484.X, M485.X, M80.X, M810.X, Z87310 | F38: S02.X, S12.X, S22.X, S32.X, S42.X, S52.X, S62.X, S72.X, S82.X, S92.X, M484.X, M485.X, M80.X, M810.X, Z87310 | I38: 162.X, 163.X, 164.X, 1650, 1651, 1652, 1653, 1654, 1655, 1656 | Q38: NO | U38: No
A39: Amy | B39: Vitamin D deficiant | C39: vitD_def | D39: 268, 268.9 | E39: E55, E55.9
A40: Amy | B40: Vitamin D deficiant including death certificate | C40: vitD_def_death | D40: 268, 268.9 | E40: E55, E55.9 | F40: E55, E55.9
...

Sheet Settings
A1: Setting | B1: Value | C1: CVDset | D1: Cancerset
A2: Filename | B2: Test | C2: CVD | D2: Cancer
A3: diabetes
A4: =Definitions!C2 -> aa | C4: Y
A5: =Definitions!C3 -> cad_hard
A6: =Definitions!C4 -> cad_int | C6: Y
A7: =Definitions!C5 -> cad_soft
A8: =Definitions!C6 -> hf_cmp
A9: =Definitions!C7 -> taa | C9: Y
A10: =Definitions!C8 -> ukb_ich | C10: Y
A11: =Definitions!C9 -> ukb_mi | C11: Y
A12: =Definitions!C10 -> ukb_nstemi | C12: Y
A13: =Definitions!C11 -> ukb_sah | C13: Y
A14: =Definitions!C12 -> ukb_stemi | C14: Y
A15: =Definitions!C13 -> ukb_stri | C15: Y
A16: =Definitions!C14 -> ukb_stroke | C16: Y
A17: =Definitions!C15 -> vte | C17: Y
A18: =Definitions!C16 -> sch_1
A19: =Definitions!C17 -> sch_2
A20: =Definitions!C18 -> ca_all | D20: Y
A21: =Definitions!C19 -> aftap
A22: =Definitions!C20 -> afta
A23: =Definitions!C21 -> fof
A24: =Definitions!C22 -> osteo
A25: =Definitions!C23 -> osteo_plus
A26: =Definitions!C24 -> frac_fore
A27: =Definitions!C25 -> frac_arm
A28: =Definitions!C26 -> frac_hip
A29: =Definitions!C27 -> frac_vert
A30: =Definitions!C28 -> frac_pelvis
A31: =Definitions!C29 -> frac_femur
A32: =Definitions!C30 -> frac_leg
... A52: =Definitions!C50 -> hemianopia
A53: =Definitions!C51 -> aost | C53: Y
A54: =Definitions!C52 -> aost_wide
A55: =Definitions!C53 -> CHD_death
A56: =Definitions!C54 -> i_stroke_death
A57: =Definitions!C55 -> ish_hf
A58: =Definitions!C56 -> pe_thm
A59: =Definitions!C57 -> ptca_cabg
...

Sheet Read_V3
A1: read_code | B1: icd10_code | C1: mapping_status
A2: 123.. | B2: Z831 | C2: D
A3: 12A.. | B3: Z835 | C3: D
A4: 12DZ. | B4: Z836 | C4: D
A5: 136K. | B5: F100 | C5: D
A6: 13CE. | B6: R268 | C6: D
A7: 13FF. | B7: Z598 | C7: D
A8: 13FF2 | B8: Z598 | C8: D
A9: 13G1. | B9: Z741 | C9: D
A10: 13G2. | B10: Z741 | C10: D
A11: 13G61 | B11: Z741 | C11: D
A12: 13H8. | B12: Z640 | C12: D
... A35: 14U.. | B35: Z939 | C35: D
A36: 1512 | B36: N951 | C36: D
A37: 15A2. | B37: Z924 | C37: D
A38: 1624 | B38: R635 | C38: D
A39: 1632 | B39: R633 | C39: D
A40: 1633 | B40: R633 | C40: D
A41: 166.. | B41: R619 | C41: D
A42: 166Z. | B42: R619 | C42: D
A43: 1682 | B43: R53X | C43: D
A44: 16A2. | B44: M436 | C44: D
A45: 16AZ. | B45: M436 | C45: D
A46: 16B.. | B46: R233 | C46: D
A47: 16B3. | B47: R233 | C47: D
A48: 16BZ. | B48: R233 | C48: D
A49: 16C.. | B49: M549 | C49: D
A50: 16C2. | B50: M549 | C50: D
A51: 16C6. | B51: M549 | C51: D
A52: 16CZ. | B52: M549 | C52: D
A53: 171C. | B53: R05X | C53: D
A54: 171D. | B54: R05X | C54: D
A55: 171Z. | B55: R05X | C55: D
... A57: 173B. | B57: R062 | C57: D
A58: 1813 | B58: R002 | C58: D
A59: 181Z. | B59: R002 | C59: D
A60: 182.. | B60: R074 | C60: D
A61: 1822 | B61: R072 | C61: D
A62: 1823 | B62: R072 | C62: D
A63: 1828 | B63: R074 | C63: D
...

Sheet Read_V2
A1: read_code | B1: icd10_code | C1: icd10_code_def
A2: A00.. | B2: A00 | C2: 1
A3: A000. | B3: A000 | C3: 1
A4: A001. | B4: A001 | C4: 1
A5: A00z. | B5: A009 | C5: 1
A6: A01.. | B6: A01 | C6: 1
A7: A010. | B7: A010 | C7: 1
A8: A011. | B8: A011 | C8: 1
A9: A012. | B9: A012 | C9: 1
A10: A013. | B10: A013 | C10: 1
A11: A01z. | B11: A014 | C11: 1
A12: A02.. | B12: A02 | C12: 1
A13: A020. | B13: A020 | C13: 1
... A16384: N061T | B16384: M125 | C16384: 1

Sheet cancer_sub
A1: Completer | B1: Outcome name | C1: Subset name | D1: Suggested variable name | E1: ICD-9 codes | F1: ICD-10 codes | G1: Death 40001, 40002 | H1: Cancer Histology | I1: Self-report 20001 | J1: Self-report 20002 | K1: Self-report 20004 | L1: Self-report 6150 | M1: Self-report 6152 | N1: Self-report 6153 | O1: Self-report 6177 | P1: Procedures OPCS4 | Q1: Procedures OPCS3 | R1: Use Primary Care | S1: Match ICD10 Primary Care Codes | T1: Read V3 Primary Care Codes | U1: Read V2 Primary Care Codes | V1: Prevalent/Incident | W1: Comments on definition | X1: Other comments
E2: Fields used (40013, 40017, 41203, 41205) | F2: (40006, 40016, 41202, 41204 ) | G2: 40001, 40002 | H2: 40011
A3: Paul/Matt | B3: Breast Ca | C3: ca_breast | D3: ca_breast | E3: 174.X, 175.X, V10.3 | F3: C50.X, Z85.3 | G3: C50.X, Z85.3 | I3: 1002 | R3: No | V3: Yes
A4: Paul/Matt | B4: Prostate Ca | C4: ca_prost | D4: ca_prost | E4: 185.X, V10.46 | F4: C61.X, Z85.46 | G4: C61.X, Z85.46 | I4: 1044 | R4: No | V4: Yes
A5: Paul/Matt | B5: Lung Ca | C5: ca_lung | D5: ca_lung | E5: 162.X, V10.1 | F5: C33.X, C34.X, C39.9, Z85.1 | G5: C33.X, C34.X, C39.9, Z85.1 | I5: 1001, 1027, 1028, 1080 | R5: No | V5: Yes
B6: Squamous | C6: ca_lung | D6: lung_squa | H6: 8070 | R6: No | V6: Yes
B7: Adeno | C7: ca_lung | D7: lung_adeno | H7: 8140, 8255, 8480, 8481, 8490 | R7: No | V7: Yes
B8: NSCLC | C8: ca_lung | D8: lung_NSC | H8: 8070, 8140, 8255, 8480, 8481, 8490, 8046, 8012, 8013, 8014, 8560, | I8: 1028 | R8: No | V8: Yes
A9: Paul/Matt | B9: Bowel Ca | C9: ca_bowel | D9: ca_bowel | E9: 153.X, 154.0, 154.1, V10.05, V10.06 | F9: C18.X, C19.X, C20.X, Z85.038, Z85.048 | G9: C18.X, C19.X, C20.X, Z85.038, Z85.048 | I9: 1020, 1022, 1023 | R9: No | V9: Yes
A10: Paul/Matt | B10: Melanoma | C10: ca_mel | D10: ca_mel | E10: 172.X, V10.82 | F10: C43.X, Z85.820 | G10: C43.X, Z85.820 | I10: 1059 | R10: No | V10: Yes
A11: Paul/Matt | B11: NHL | C11: ca_nhl | D11: ca_nhl | E11: 200.X, 202.0 , 202.1, 202.2, 202.7, V10.71 | F11: C82.X, C83.X, C84.X, C85.X, C86.X, C88.0, C88.4, Z85.72 | G11: C82.X, C83.X, C84.X, C85.X, C86.X, C88.0, C88.4, Z85.72 | I11: 1053 | R11: No | V11: Yes
B12: Diffuse Large Cell | C12: ca_nhl | D12: NHL_DLBC | F12: C83.3 | G12: C83.3 | H12: 9680, 9684, | R12: No | V12: Yes
B13: Follicular | C13: ca_nhl | D13: NHL_fol | F13: C82.X | G13: C82.X | H13: 9690, 9691, 9695, 9698 | R13: No | V13: Yes
A14: Paul/Matt | B14: Kidney Ca | C14: ca_kid | D14: ca_kid | E14: 189.0, V10.52 | F14: C64.X, Z85.528 | G14: C64.X, Z85.528 | I14: 1034 | R14: No | V14: Yes
A15: Paul/Matt | B15: Head and Neck Ca | C15: ca_headneck | D15: ca_headneck | E15: 140.X, 141.X, 142.X, 143.X, 144.X, 145.X, 146.X, 147.X, 148.X, 149.X, 160.X, 161.X, V10.01, V10.02, V10.21, V10.22, | F15: C00.X, C01.X, C02.X, C03.X, C04.X, C05.X, C06.X, C07.X, C08.X, C09.X, C10.X, C11.X, C12.X, C13.X, C14.X, C30.X, C31.X, C32.X, Z85.21, Z85.22, Z85.81 | G15: C00.X, C01.X, C02.X, C03.X, C04.X, C05.X, C06.X, C07.X, C08.X, C09.X, C10.X, C11.X, C12.X, C13.X, C14.X, C30.X, C31.X, C32.X, Z85.21, Z85.22, Z85.81 | I15: 1006, 1007, 1009, 1004, 1010, 1011, 1012, 1077, 1078, 1079, 1005, 1015, 1016, | R15: No | V15: Yes
B16: Oral and orapharngeal | C16: ca_headneck | D16: head_oral | E16: 146.X, 140.X, 141.X, 143.X, 144.X, 145.X, 149.8, 149.9, V10.01, V10.02 | F16: C10.X, C00.X, C01.X, C02.X, C03.X, C04.X, C05.X, C06.X, C09.X, | G16: C10.X, C00.X, C01.X, C02.X, C03.X, C04.X, C05.X, C06.X, C09.X | I16: 1004, 1010, 1011, 1012, 1077, 1078, 1079, | R16: No | V16: Yes
B17: Laryngeal and hypopharyngeal | C17: ca_headneck | D17: head_lar | E17: 148.X, 161.X, V10.21 | F17: C12.X, C13.X, C32.X, Z85.21 | G17: C12.X, C13.X, C32.X, Z85.21 | I17: 1006 | R17: No | V17: Yes
A18: Paul/Matt | B18: Brain/CNS/Intracranial | C18: ca_brain | D18: ca_brain | E18: 191.X, 192.0, 192.1, 192.2, 192.3, V10.85 | F18: C70.X, C71.X, C72.0, C72.3, Z85.841 | G18: C70.X, C71.X, C72.0, C72.3, Z85.841 | I18: 1031, 1032, 1033 | R18: No | V18: Yes
A19: Paul/Matt | B19: Bladder Ca | C19: ca_blad | D19: ca_blad | E19: 188.X, 189.1, 189.2, V10.51, V10.53 | F19: C67.X, C65.X, C66.X, Z85.51, Z85.54, Z85.53 | G19: C67.X, C65.X, C66.X, Z85.51, Z85.54, Z85.53 | I19: 1035 | R19: No | V19: Yes
A20: Paul/Matt | B20: Pancreatic Ca | C20: ca_panc | D20: ca_panc | E20: 157.X | F20: C25.X, Z85.07 | G20: C25.X, Z85.07 | I20: 1034 | R20: No | V20: Yes
A21: Paul/Matt | B21: Uterine ca | C21: ca_uter | D21: ca_uter | E21: 179.X, 182.X, V10.42, | F21: C54.X, C55.X, Z85.42 | G21: C54.X, C55.X, Z85.42 | I21: 1040 | R21: No | V21: Yes
A22: Paul/Matt | B22: Leukaemia | C22: ca_leuk | D22: ca_leuk | E22: 204.X, 205.X, 206.X, 207.X, 208.X, V10.6 | F22: C91.X, C92.X, C93.X, C94.0, C94.2, C94.3, C94.4, C94.8, C95, Z85.6 | G22: C91.X, C92.X, C93.X, C94.0, C94.2, C94.3, C94.4, C94.8, C95, Z85.6 | I22: 1048, 1055, 1056, 1074 | R22: No | V22: Yes
B23: AML | C23: ca_leuk | D23: leuk_aml | E23: 205.0, 205.3, 206.0, 207.0, | F23: C92.0, C92.3, C92.4, C92.5, C92.6, C92.A, C93.0, C94.0, C94.2, C94.3, C94.4 | G23: C92.0, C92.3, C92.4, C92.5, C92.6, C92.A, C93.0, C94.0, C94.2, C94.3, C94.4 | I23: 1074 | R23: No | V23: Yes
B24: CLL | C24: ca_leuk | D24: leuk_cll | E24: 204.1 | F24: C91.1, C91.3, C91.4, C91.6 | G24: C91.1, C91.3, C91.4, C91.6 | I24: 1055 | R24: No | V24: Yes
A25: Paul/Matt | B25: Oesophageal Ca | C25: ca_oeso | D25: ca_oeso | E25: 150.X, V10.03 | F25: C15.X, Z85.01 | G25: C15.X, Z85.01 | I25: 1017 | R25: No | V25: Yes
A26: Paul/Matt | B26: Ovarian Ca | C26: ca_ov | D26: ca_ov | E26: 183.0, 183.2, 183.8, 183.9, V10.43 | F26: C56.X, C57.0, C57.4, Z85.43 | G26: C56.X, C57.0, C57.4, Z85.43 | I26: 1039 | R26: No | V26: Yes
A27: Paul/Matt | B27: Stomach ca | C27: ca_gastric | D27: ca_gastric | E27: 151.X, V10.04 | F27: C16.X, Z85.028 | G27: C16.X, Z85.028 | I27: 1018 | R27: No | V27: Yes
A28: Paul/Matt | B28: Liver Ca | C28: ca_hep | D28: ca_hep | E28: 155.0 | F28: C22.0 | G28: C22.0 | H28: 8170, 8171, 8172, 8173, 8174, 8175 | I28: 1024 | R28: No | V28: Yes
A29: Paul/Matt | B29: Myeloma | C29: ca_myeloma | D29: ca_myeloma | E29: 203.0, 203.1, | F29: C90.0, C90.1 | G29: C90.0, C90.1 | H29: 9732, 9733 | I29: 1050 | R29: No | V29: Yes
A30: Paul/Matt | B30: Thyroid | C30: ca_thyroid | D30: ca_thyroid | E30: 193.X, V10.87 | F30: C73.X. Z85.850 | G30: C73.X. Z85.850 | I30: 1065 | R30: No | V30: Yes
A31: Paul/Matt | B31: Biliary | C31: ca_bil | D31: ca_bil | E31: 155.1, 156.0 | F31: C22.1, C23.X, C24.X | G31: C22.1, C23.X, C24.X | I31: 1025 | R31: No | V31: Yes
A32: Paul/Matt | B32: Cervical | C32: ca_cerv | D32: ca_cerv | E32: 180.X, V10.41 | F32: C53.X, Z85.41 | G32: C53.X, Z85.41 | I32: 1041 | R32: No | V32: Yes
A33: Paul/Matt | B33: Testicular | C33: ca_test | D33: ca_test | E33: 186.X, V10.47 | F33: C62.X, Z85.47 | G33: C62.X, Z85.47 | I33: 1045 | R33: No | V33: Yes
A34: Amy | B34: All Cancer | C34: ca_all | D34: ca_all | E34: 14.X, 15.X,16.X,17.X, 18.X, 19.X, 20.X, V10.X | F34: C.X, Z85.X | G34: C.X, Z85.X | H34: .X | I34: .X | R34: No | V34: Yes
